Workbook

Sheet דשבורד
A1: עוצמה גדודית — לוח בקרה חי
A2: מחושב אוטומטית מלשונית "טבלת ניהול" (טווחים רגילים, תואם Google Sheets) | T2: =IFERROR(SMALL('טבלת ניהול'!$Q$3:$Q$400,1),"")
T3: =IFERROR(SMALL('טבלת ניהול'!$Q$3:$Q$400,2),"")
A4: סך פריטים | B4: חוסרים | C4: עודפים | D4: תקין | E4: ללא מצאי | F4: יח' חסרות | G4: יח' עודפות | T4: =IFERROR(SMALL('טבלת ניהול'!$Q$3:$Q$400,3),"")
A5: =COUNTA('טבלת ניהול'!$B$3:$B$400) | B5: =COUNTIF('טבלת ניהול'!$O$3:$O$400,"חוסר") | C5: =COUNTIF('טבלת ניהול'!$O$3:$O$400,"עודף") | D5: =COUNTIF('טבלת ניהול'!$O$3:$O$400,"תקין") | E5: =COUNTIF('טבלת ניהול'!$O$3:$O$400,"אין מצאי") | F5: =-SUMIF('טבלת ניהול'!$M$3:$M$400,"<0") | G5: =SUMIF('טבלת ניהול'!$M$3:$M$400,">0") | T5: =IFERROR(SMALL('טבלת ניהול'!$Q$3:$Q$400,4),"")
T6: =IFERROR(SMALL('טבלת ניהול'!$Q$3:$Q$400,5),"")
T7: =IFERROR(SMALL('טבלת ניהול'!$Q$3:$Q$400,6),"")
A8: חוסרים מובילים (מתעדכן) | E8: עודפים מובילים (מתעדכן) | T8: =IFERROR(SMALL('טבלת ניהול'!$Q$3:$Q$400,7),"")
A9: אמצעי | B9: סך הכל | C9: מצאי | D9: פער | E9: אמצעי | F9: סך הכל | G9: מצאי | H9: פער | T9: =IFERROR(SMALL('טבלת ניהול'!$Q$3:$Q$400,8),"")
A10: =IFERROR(INDEX('טבלת ניהול'!$B$3:$B$400,MATCH($T$2,'טבלת ניהול'!$Q$3:$Q$400,0)),"") | B10: =IFERROR(INDEX('טבלת ניהול'!$K$3:$K$400,MATCH($T$2,'טבלת ניהול'!$Q$3:$Q$400,0)),"") | C10: =IFERROR(INDEX('טבלת ניהול'!$L$3:$L$400,MATCH($T$2,'טבלת ניהול'!$Q$3:$Q$400,0)),"") | D10: =IFERROR(INDEX('טבלת ניהול'!$M$3:$M$400,MATCH($T$2,'טבלת ניהול'!$Q$3:$Q$400,0)),"") | E10: =IFERROR(INDEX('טבלת ניהול'!$B$3:$B$400,MATCH($T$20,'טבלת ניהול'!$Q$3:$Q$400,0)),"") | F10: =IFERROR(INDEX('טבלת ניהול'!$K$3:$K$400,MATCH($T$20,'טבלת ניהול'!$Q$3:$Q$400,0)),"") | G10: =IFERROR(INDEX('טבלת ניהול'!$L$3:$L$400,MATCH($T$20,'טבלת ניהול'!$Q$3:$Q$400,0)),"") | H10: =IFERROR(INDEX('טבלת ניהול'!$M$3:$M$400,MATCH($T$20,'טבלת ניהול'!$Q$3:$Q$400,0)),"") | T10: =IFERROR(SMALL('טבלת ניהול'!$Q$3:$Q$400,9),"")
A11: =IFERROR(INDEX('טבלת ניהול'!$B$3:$B$400,MATCH($T$3,'טבלת ניהול'!$Q$3:$Q$400,0)),"") | B11: =IFERROR(INDEX('טבלת ניהול'!$K$3:$K$400,MATCH($T$3,'טבלת ניהול'!$Q$3:$Q$400,0)),"") | C11: =IFERROR(INDEX('טבלת ניהול'!$L$3:$L$400,MATCH($T$3,'טבלת ניהול'!$Q$3:$Q$400,0)),"") | D11: =IFERROR(INDEX('טבלת ניהול'!$M$3:$M$400,MATCH($T$3,'טבלת ניהול'!$Q$3:$Q$400,0)),"") | E11: =IFERROR(INDEX('טבלת ניהול'!$B$3:$B$400,MATCH($T$21,'טבלת ניהול'!$Q$3:$Q$400,0)),"") | F11: =IFERROR(INDEX('טבלת ניהול'!$K$3:$K$400,MATCH($T$21,'טבלת ניהול'!$Q$3:$Q$400,0)),"") | G11: =IFERROR(INDEX('טבלת ניהול'!$L$3:$L$400,MATCH($T$21,'טבלת ניהול'!$Q$3:$Q$400,0)),"") | H11: =IFERROR(INDEX('טבלת ניהול'!$M$3:$M$400,MATCH($T$21,'טבלת ניהול'!$Q$3:$Q$400,0)),"") | T11: =IFERROR(SMALL('טבלת ניהול'!$Q$3:$Q$400,10),"")
A12: =IFERROR(INDEX('טבלת ניהול'!$B$3:$B$400,MATCH($T$4,'טבלת ניהול'!$Q$3:$Q$400,0)),"") | B12: =IFERROR(INDEX('טבלת ניהול'!$K$3:$K$400,MATCH($T$4,'טבלת ניהול'!$Q$3:$Q$400,0)),"") | C12: =IFERROR(INDEX('טבלת ניהול'!$L$3:$L$400,MATCH($T$4,'טבלת ניהול'!$Q$3:$Q$400,0)),"") | D12: =IFERROR(INDEX('טבלת ניהול'!$M$3:$M$400,MATCH($T$4,'טבלת ניהול'!$Q$3:$Q$400,0)),"") | E12: =IFERROR(INDEX('טבלת ניהול'!$B$3:$B$400,MATCH($T$22,'טבלת ניהול'!$Q$3:$Q$400,0)),"") | F12: =IFERROR(INDEX('טבלת ניהול'!$K$3:$K$400,MATCH($T$22,'טבלת ניהול'!$Q$3:$Q$400,0)),"") | G12: =IFERROR(INDEX('טבלת ניהול'!$L$3:$L$400,MATCH($T$22,'טבלת ניהול'!$Q$3:$Q$400,0)),"") | H12: =IFERROR(INDEX('טבלת ניהול'!$M$3:$M$400,MATCH($T$22,'טבלת ניהול'!$Q$3:$Q$400,0)),"") | T12: =IFERROR(SMALL('טבלת ניהול'!$Q$3:$Q$400,11),"")
A13: =IFERROR(INDEX('טבלת ניהול'!$B$3:$B$400,MATCH($T$5,'טבלת ניהול'!$Q$3:$Q$400,0)),"") | B13: =IFERROR(INDEX('טבלת ניהול'!$K$3:$K$400,MATCH($T$5,'טבלת ניהול'!$Q$3:$Q$400,0)),"") | C13: =IFERROR(INDEX('טבלת ניהול'!$L$3:$L$400,MATCH($T$5,'טבלת ניהול'!$Q$3:$Q$400,0)),"") | D13: =IFERROR(INDEX('טבלת ניהול'!$M$3:$M$400,MATCH($T$5,'טבלת ניהול'!$Q$3:$Q$400,0)),"") | E13: =IFERROR(INDEX('טבלת ניהול'!$B$3:$B$400,MATCH($T$23,'טבלת ניהול'!$Q$3:$Q$400,0)),"") | F13: =IFERROR(INDEX('טבלת ניהול'!$K$3:$K$400,MATCH($T$23,'טבלת ניהול'!$Q$3:$Q$400,0)),"") | G13: =IFERROR(INDEX('טבלת ניהול'!$L$3:$L$400,MATCH($T$23,'טבלת ניהול'!$Q$3:$Q$400,0)),"") | H13: =IFERROR(INDEX('טבלת ניהול'!$M$3:$M$400,MATCH($T$23,'טבלת ניהול'!$Q$3:$Q$400,0)),"") | T13: =IFERROR(SMALL('טבלת ניהול'!$Q$3:$Q$400,12),"")
A14: =IFERROR(INDEX('טבלת ניהול'!$B$3:$B$400,MATCH($T$6,'טבלת ניהול'!$Q$3:$Q$400,0)),"") | B14: =IFERROR(INDEX('טבלת ניהול'!$K$3:$K$400,MATCH($T$6,'טבלת ניהול'!$Q$3:$Q$400,0)),"") | C14: =IFERROR(INDEX('טבלת ניהול'!$L$3:$L$400,MATCH($T$6,'טבלת ניהול'!$Q$3:$Q$400,0)),"") | D14: =IFERROR(INDEX('טבלת ניהול'!$M$3:$M$400,MATCH($T$6,'טבלת ניהול'!$Q$3:$Q$400,0)),"") | E14: =IFERROR(INDEX('טבלת ניהול'!$B$3:$B$400,MATCH($T$24,'טבלת ניהול'!$Q$3:$Q$400,0)),"") | F14: =IFERROR(INDEX('טבלת ניהול'!$K$3:$K$400,MATCH($T$24,'טבלת ניהול'!$Q$3:$Q$400,0)),"") | G14: =IFERROR(INDEX('טבלת ניהול'!$L$3:$L$400,MATCH($T$24,'טבלת ניהול'!$Q$3:$Q$400,0)),"") | H14: =IFERROR(INDEX('טבלת ניהול'!$M$3:$M$400,MATCH($T$24,'טבלת ניהול'!$Q$3:$Q$400,0)),"")
A15: =IFERROR(INDEX('טבלת ניהול'!$B$3:$B$400,MATCH($T$7,'טבלת ניהול'!$Q$3:$Q$400,0)),"") | B15: =IFERROR(INDEX('טבלת ניהול'!$K$3:$K$400,MATCH($T$7,'טבלת ניהול'!$Q$3:$Q$400,0)),"") | C15: =IFERROR(INDEX('טבלת ניהול'!$L$3:$L$400,MATCH($T$7,'טבלת ניהול'!$Q$3:$Q$400,0)),"") | D15: =IFERROR(INDEX('טבלת ניהול'!$M$3:$M$400,MATCH($T$7,'טבלת ניהול'!$Q$3:$Q$400,0)),"") | E15: =IFERROR(INDEX('טבלת ניהול'!$B$3:$B$400,MATCH($T$25,'טבלת ניהול'!$Q$3:$Q$400,0)),"") | F15: =IFERROR(INDEX('טבלת ניהול'!$K$3:$K$400,MATCH($T$25,'טבלת ניהול'!$Q$3:$Q$400,0)),"") | G15: =IFERROR(INDEX('טבלת ניהול'!$L$3:$L$400,MATCH($T$25,'טבלת ניהול'!$Q$3:$Q$400,0)),"") | H15: =IFERROR(INDEX('טבלת ניהול'!$M$3:$M$400,MATCH($T$25,'טבלת ניהול'!$Q$3:$Q$400,0)),"")
A16: =IFERROR(INDEX('טבלת ניהול'!$B$3:$B$400,MATCH($T$8,'טבלת ניהול'!$Q$3:$Q$400,0)),"") | B16: =IFERROR(INDEX('טבלת ניהול'!$K$3:$K$400,MATCH($T$8,'טבלת ניהול'!$Q$3:$Q$400,0)),"") | C16: =IFERROR(INDEX('טבלת ניהול'!$L$3:$L$400,MATCH($T$8,'טבלת ניהול'!$Q$3:$Q$400,0)),"") | D16: =IFERROR(INDEX('טבלת ניהול'!$M$3:$M$400,MATCH($T$8,'טבלת ניהול'!$Q$3:$Q$400,0)),"")
A17: =IFERROR(INDEX('טבלת ניהול'!$B$3:$B$400,MATCH($T$9,'טבלת ניהול'!$Q$3:$Q$400,0)),"") | B17: =IFERROR(INDEX('טבלת ניהול'!$K$3:$K$400,MATCH($T$9,'טבלת ניהול'!$Q$3:$Q$400,0)),"") | C17: =IFERROR(INDEX('טבלת ניהול'!$L$3:$L$400,MATCH($T$9,'טבלת ניהול'!$Q$3:$Q$400,0)),"") | D17: =IFERROR(INDEX('טבלת ניהול'!$M$3:$M$400,MATCH($T$9,'טבלת ניהול'!$Q$3:$Q$400,0)),"")
A18: =IFERROR(INDEX('טבלת ניהול'!$B$3:$B$400,MATCH($T$10,'טבלת ניהול'!$Q$3:$Q$400,0)),"") | B18: =IFERROR(INDEX('טבלת ניהול'!$K$3:$K$400,MATCH($T$10,'טבלת ניהול'!$Q$3:$Q$400,0)),"") | C18: =IFERROR(INDEX('טבלת ניהול'!$L$3:$L$400,MATCH($T$10,'טבלת ניהול'!$Q$3:$Q$400,0)),"") | D18: =IFERROR(INDEX('טבלת ניהול'!$M$3:$M$400,MATCH($T$10,'טבלת ניהול'!$Q$3:$Q$400,0)),"")
A19: =IFERROR(INDEX('טבלת ניהול'!$B$3:$B$400,MATCH($T$11,'טבלת ניהול'!$Q$3:$Q$400,0)),"") | B19: =IFERROR(INDEX('טבלת ניהול'!$K$3:$K$400,MATCH($T$11,'טבלת ניהול'!$Q$3:$Q$400,0)),"") | C19: =IFERROR(INDEX('טבלת ניהול'!$L$3:$L$400,MATCH($T$11,'טבלת ניהול'!$Q$3:$Q$400,0)),"") | D19: =IFERROR(INDEX('טבלת ניהול'!$M$3:$M$400,MATCH($T$11,'טבלת ניהול'!$Q$3:$Q$400,0)),"")
A20: =IFERROR(INDEX('טבלת ניהול'!$B$3:$B$400,MATCH($T$12,'טבלת ניהול'!$Q$3:$Q$400,0)),"") | B20: =IFERROR(INDEX('טבלת ניהול'!$K$3:$K$400,MATCH($T$12,'טבלת ניהול'!$Q$3:$Q$400,0)),"") | C20: =IFERROR(INDEX('טבלת ניהול'!$L$3:$L$400,MATCH($T$12,'טבלת ניהול'!$Q$3:$Q$400,0)),"") | D20: =IFERROR(INDEX('טבלת ניהול'!$M$3:$M$400,MATCH($T$12,'טבלת ניהול'!$Q$3:$Q$400,0)),"") | T20: =IFERROR(IF(LARGE('טבלת ניהול'!$Q$3:$Q$400,1)>0,LARGE('טבלת ניהול'!$Q$3:$Q$400,1),""),"")
A21: =IFERROR(INDEX('טבלת ניהול'!$B$3:$B$400,MATCH($T$13,'טבלת ניהול'!$Q$3:$Q$400,0)),"") | B21: =IFERROR(INDEX('טבלת ניהול'!$K$3:$K$400,MATCH($T$13,'טבלת ניהול'!$Q$3:$Q$400,0)),"") | C21: =IFERROR(INDEX('טבלת ניהול'!$L$3:$L$400,MATCH($T$13,'טבלת ניהול'!$Q$3:$Q$400,0)),"") | D21: =IFERROR(INDEX('טבלת ניהול'!$M$3:$M$400,MATCH($T$13,'טבלת ניהול'!$Q$3:$Q$400,0)),"") | T21: =IFERROR(IF(LARGE('טבלת ניהול'!$Q$3:$Q$400,2)>0,LARGE('טבלת ניהול'!$Q$3:$Q$400,2),""),"")
T22: =IFERROR(IF(LARGE('טבלת ניהול'!$Q$3:$Q$400,3)>0,LARGE('טבלת ניהול'!$Q$3:$Q$400,3),""),"")
T23: =IFERROR(IF(LARGE('טבלת ניהול'!$Q$3:$Q$400,4)>0,LARGE('טבלת ניהול'!$Q$3:$Q$400,4),""),"")
T24: =IFERROR(IF(LARGE('טבלת ניהול'!$Q$3:$Q$400,5)>0,LARGE('טבלת ניהול'!$Q$3:$Q$400,5),""),"")
T25: =IFERROR(IF(LARGE('טבלת ניהול'!$Q$3:$Q$400,6)>0,LARGE('טבלת ניהול'!$Q$3:$Q$400,6),""),"")

Sheet טבלת ניהול
A1: טבלת עוצמה גדודית — גדוד 28 | ניהול חי (Google Sheets)
A2: קטגוריה | B2: אמצעי | C2: פלוגה א | D2: פלוגה ב | E2: פלוגה ג | F2: מסייעת | G2: פתן | H2: חפק | I2: מפקדה | J2: מלאי | K2: סך הכל | L2: מצאי | M2: פער | N2: אחוז מימוש | O2: סטטוס | P2: הערות | Q2: מפתח
A3: נשק ומקלעים | B3: M16 | J3: 173 | K3: =IF($B3="","",SUM(C3:J3)) | M3: =IF(OR($B3="",L3=""),"",K3-L3) | N3: =IF(OR($B3="",L3="",L3=0),"",K3/L3) | O3: =IF($B3="","",IF(L3="","אין מצאי",IF(K3<L3,"חוסר",IF(K3>L3,"עודף","תקין")))) | Q3: =IF(O3="חוסר",M3-ROW()/100000,IF(O3="עודף",M3+ROW()/100000,""))
A4: נשק ומקלעים | B4: M16 | I4: 12 | J4: 161 | K4: =IF($B4="","",SUM(C4:J4)) | L4: 173 | M4: =IF(OR($B4="",L4=""),"",K4-L4) | N4: =IF(OR($B4="",L4="",L4=0),"",K4/L4) | O4: =IF($B4="","",IF(L4="","אין מצאי",IF(K4<L4,"חוסר",IF(K4>L4,"עודף","תקין")))) | Q4: =IF(O4="חוסר",M4-ROW()/100000,IF(O4="עודף",M4+ROW()/100000,""))
A5: נשק ומקלעים | B5: זאבון | K5: =IF($B5="","",SUM(C5:J5)) | M5: =IF(OR($B5="",L5=""),"",K5-L5) | N5: =IF(OR($B5="",L5="",L5=0),"",K5/L5) | O5: =IF($B5="","",IF(L5="","אין מצאי",IF(K5<L5,"חוסר",IF(K5>L5,"עודף","תקין")))) | Q5: =IF(O5="חוסר",M5-ROW()/100000,IF(O5="עודף",M5+ROW()/100000,""))
A6: נשק ומקלעים | B6: מאג | J6: 25 | K6: =IF($B6="","",SUM(C6:J6)) | L6: 23 | M6: =IF(OR($B6="",L6=""),"",K6-L6) | N6: =IF(OR($B6="",L6="",L6=0),"",K6/L6) | O6: =IF($B6="","",IF(L6="","אין מצאי",IF(K6<L6,"חוסר",IF(K6>L6,"עודף","תקין")))) | Q6: =IF(O6="חוסר",M6-ROW()/100000,IF(O6="עודף",M6+ROW()/100000,""))
A7: נשק ומקלעים | B7: מטול+זאבון | C7: 7 | D7: 8 | E7: 6 | F7: 6 | G7: 2 | H7: 1 | J7: 1 | K7: =IF($B7="","",SUM(C7:J7)) | L7: 31 | M7: =IF(OR($B7="",L7=""),"",K7-L7) | N7: =IF(OR($B7="",L7="",L7=0),"",K7/L7) | O7: =IF($B7="","",IF(L7="","אין מצאי",IF(K7<L7,"חוסר",IF(K7>L7,"עודף","תקין")))) | Q7: =IF(O7="חוסר",M7-ROW()/100000,IF(O7="עודף",M7+ROW()/100000,""))
A8: נשק ומקלעים | B8: מפרו לייט קצר | K8: =IF($B8="","",SUM(C8:J8)) | M8: =IF(OR($B8="",L8=""),"",K8-L8) | N8: =IF(OR($B8="",L8="",L8=0),"",K8/L8) | O8: =IF($B8="","",IF(L8="","אין מצאי",IF(K8<L8,"חוסר",IF(K8>L8,"עודף","תקין")))) | Q8: =IF(O8="חוסר",M8-ROW()/100000,IF(O8="עודף",M8+ROW()/100000,""))
A9: נשק ומקלעים | B9: מקלע נגב קל | C9: 4 | D9: 6 | E9: 3 | F9: 3 | H9: 2 | J9: 7 | K9: =IF($B9="","",SUM(C9:J9)) | L9: 31 | M9: =IF(OR($B9="",L9=""),"",K9-L9) | N9: =IF(OR($B9="",L9="",L9=0),"",K9/L9) | O9: =IF($B9="","",IF(L9="","אין מצאי",IF(K9<L9,"חוסר",IF(K9>L9,"עודף","תקין")))) | Q9: =IF(O9="חוסר",M9-ROW()/100000,IF(O9="עודף",M9+ROW()/100000,""))
A10: נשק ומקלעים | B10: מקלרון | J10: 2 | K10: =IF($B10="","",SUM(C10:J10)) | L10: 2 | M10: =IF(OR($B10="",L10=""),"",K10-L10) | N10: =IF(OR($B10="",L10="",L10=0),"",K10/L10) | O10: =IF($B10="","",IF(L10="","אין מצאי",IF(K10<L10,"חוסר",IF(K10>L10,"עודף","תקין")))) | Q10: =IF(O10="חוסר",M10-ROW()/100000,IF(O10="עודף",M10+ROW()/100000,""))
A11: נשק ומקלעים | B11: נגב 7.62 | C11: 2 | D11: 1 | E11: 2 | F11: 2 | J11: 1 | K11: =IF($B11="","",SUM(C11:J11)) | L11: 8 | M11: =IF(OR($B11="",L11=""),"",K11-L11) | N11: =IF(OR($B11="",L11="",L11=0),"",K11/L11) | O11: =IF($B11="","",IF(L11="","אין מצאי",IF(K11<L11,"חוסר",IF(K11>L11,"עודף","תקין")))) | Q11: =IF(O11="חוסר",M11-ROW()/100000,IF(O11="עודף",M11+ROW()/100000,""))
A12: נשק ומקלעים | B12: פגיון + כוונת | C12: 1 | D12: 1 | E12: 1 | F12: 1 | J12: 1 | K12: =IF($B12="","",SUM(C12:J12)) | L12: 5 | M12: =IF(OR($B12="",L12=""),"",K12-L12) | N12: =IF(OR($B12="",L12="",L12=0),"",K12/L12) | O12: =IF($B12="","",IF(L12="","אין מצאי",IF(K12<L12,"חוסר",IF(K12>L12,"עודף","תקין")))) | Q12: =IF(O12="חוסר",M12-ROW()/100000,IF(O12="עודף",M12+ROW()/100000,""))
A13: נשק ומקלעים | B13: רוב"צ HTR 338 | F13: 4 | K13: =IF($B13="","",SUM(C13:J13)) | L13: 4 | M13: =IF(OR($B13="",L13=""),"",K13-L13) | N13: =IF(OR($B13="",L13="",L13=0),"",K13/L13) | O13: =IF($B13="","",IF(L13="","אין מצאי",IF(K13<L13,"חוסר",IF(K13>L13,"עודף","תקין")))) | Q13: =IF(O13="חוסר",M13-ROW()/100000,IF(O13="עודף",M13+ROW()/100000,""))
A14: נשק ומקלעים | B14: רוב"צ M24 | F14: 5 | K14: =IF($B14="","",SUM(C14:J14)) | L14: 8 | M14: =IF(OR($B14="",L14=""),"",K14-L14) | N14: =IF(OR($B14="",L14="",L14=0),"",K14/L14) | O14: =IF($B14="","",IF(L14="","אין מצאי",IF(K14<L14,"חוסר",IF(K14>L14,"עודף","תקין")))) | Q14: =IF(O14="חוסר",M14-ROW()/100000,IF(O14="עודף",M14+ROW()/100000,""))
A15: נשק ומקלעים | B15: רוס"ר M4 פלטופ | C15: 58 | D15: 58 | E15: 52 | F15: 79 | G15: 25 | H15: 14 | J15: 59 | K15: =IF($B15="","",SUM(C15:J15)) | L15: 347 | M15: =IF(OR($B15="",L15=""),"",K15-L15) | N15: =IF(OR($B15="",L15="",L15=0),"",K15/L15) | O15: =IF($B15="","",IF(L15="","אין מצאי",IF(K15<L15,"חוסר",IF(K15>L15,"עודף","תקין")))) | P15: מלט פסטרנק לשם | Q15: =IF(O15="חוסר",M15-ROW()/100000,IF(O15="עודף",M15+ROW()/100000,""))
A16: כוונות ואופטיקה | B16: PACK EOTECH | J16: 81 | K16: =IF($B16="","",SUM(C16:J16)) | M16: =IF(OR($B16="",L16=""),"",K16-L16) | N16: =IF(OR($B16="",L16="",L16=0),"",K16/L16) | O16: =IF($B16="","",IF(L16="","אין מצאי",IF(K16<L16,"חוסר",IF(K16>L16,"עודף","תקין")))) | Q16: =IF(O16="חוסר",M16-ROW()/100000,IF(O16="עודף",M16+ROW()/100000,""))
A17: כוונות ואופטיקה | B17: PACK שחור | J17: 51 | K17: =IF($B17="","",SUM(C17:J17)) | M17: =IF(OR($B17="",L17=""),"",K17-L17) | N17: =IF(OR($B17="",L17="",L17=0),"",K17/L17) | O17: =IF($B17="","",IF(L17="","אין מצאי",IF(K17<L17,"חוסר",IF(K17>L17,"עודף","תקין")))) | Q17: =IF(O17="חוסר",M17-ROW()/100000,IF(O17="עודף",M17+ROW()/100000,""))
A18: כוונות ואופטיקה | B18: eotech | K18: =IF($B18="","",SUM(C18:J18)) | M18: =IF(OR($B18="",L18=""),"",K18-L18) | N18: =IF(OR($B18="",L18="",L18=0),"",K18/L18) | O18: =IF($B18="","",IF(L18="","אין מצאי",IF(K18<L18,"חוסר",IF(K18>L18,"עודף","תקין")))) | Q18: =IF(O18="חוסר",M18-ROW()/100000,IF(O18="עודף",M18+ROW()/100000,""))
A19: כוונות ואופטיקה | B19: כוונת השלכה M5 | K19: =IF($B19="","",SUM(C19:J19)) | L19: 306 | M19: =IF(OR($B19="",L19=""),"",K19-L19) | N19: =IF(OR($B19="",L19="",L19=0),"",K19/L19) | O19: =IF($B19="","",IF(L19="","אין מצאי",IF(K19<L19,"חוסר",IF(K19>L19,"עודף","תקין")))) | Q19: =IF(O19="חוסר",M19-ROW()/100000,IF(O19="עודף",M19+ROW()/100000,""))
A20: כוונות ואופטיקה | B20: כוונת השלכה מתקדמת | J20: 29 | K20: =IF($B20="","",SUM(C20:J20)) | M20: =IF(OR($B20="",L20=""),"",K20-L20) | N20: =IF(OR($B20="",L20="",L20=0),"",K20/L20) | O20: =IF($B20="","",IF(L20="","אין מצאי",IF(K20<L20,"חוסר",IF(K20>L20,"עודף","תקין")))) | Q20: =IF(O20="חוסר",M20-ROW()/100000,IF(O20="עודף",M20+ROW()/100000,""))
A21: כוונות ואופטיקה | B21: כוונת טריג' | C21: 12 | D21: 14 | E21: 16 | F21: 15 | G21: 2 | H21: 4 | J21: 6 | K21: =IF($B21="","",SUM(C21:J21)) | L21: 70 | M21: =IF(OR($B21="",L21=""),"",K21-L21) | N21: =IF(OR($B21="",L21="",L21=0),"",K21/L21) | O21: =IF($B21="","",IF(L21="","אין מצאי",IF(K21<L21,"חוסר",IF(K21>L21,"עודף","תקין")))) | P21: 1 אצל מלט | Q21: =IF(O21="חוסר",M21-ROW()/100000,IF(O21="עודף",M21+ROW()/100000,""))
A22: כוונות ואופטיקה | B22: כוונת טרמית קליפאון | F22: 8 | K22: =IF($B22="","",SUM(C22:J22)) | L22: 8 | M22: =IF(OR($B22="",L22=""),"",K22-L22) | N22: =IF(OR($B22="",L22="",L22=0),"",K22/L22) | O22: =IF($B22="","",IF(L22="","אין מצאי",IF(K22<L22,"חוסר",IF(K22>L22,"עודף","תקין")))) | Q22: =IF(O22="חוסר",M22-ROW()/100000,IF(O22="עודף",M22+ROW()/100000,""))
A23: כוונות ואופטיקה | B23: כוונת לילה לצלף MUNS | F23: 4 | K23: =IF($B23="","",SUM(C23:J23)) | L23: 4 | M23: =IF(OR($B23="",L23=""),"",K23-L23) | N23: =IF(OR($B23="",L23="",L23=0),"",K23/L23) | O23: =IF($B23="","",IF(L23="","אין מצאי",IF(K23<L23,"חוסר",IF(K23>L23,"עודף","תקין")))) | Q23: =IF(O23="חוסר",M23-ROW()/100000,IF(O23="עודף",M23+ROW()/100000,""))
A24: כוונות ואופטיקה | B24: לאופולד | F24: 3 | K24: =IF($B24="","",SUM(C24:J24)) | M24: =IF(OR($B24="",L24=""),"",K24-L24) | N24: =IF(OR($B24="",L24="",L24=0),"",K24/L24) | O24: =IF($B24="","",IF(L24="","אין מצאי",IF(K24<L24,"חוסר",IF(K24>L24,"עודף","תקין")))) | Q24: =IF(O24="חוסר",M24-ROW()/100000,IF(O24="עודף",M24+ROW()/100000,""))
A25: אמר"לים ותצפית | B25: אמצעי זיהוי תהל | C25: 0 | D25: 0 | E25: 2 | F25: 1 | J25: 3 | K25: =IF($B25="","",SUM(C25:J25)) | L25: 55 | M25: =IF(OR($B25="",L25=""),"",K25-L25) | N25: =IF(OR($B25="",L25="",L25=0),"",K25/L25) | O25: =IF($B25="","",IF(L25="","אין מצאי",IF(K25<L25,"חוסר",IF(K25>L25,"עודף","תקין")))) | Q25: =IF(O25="חוסר",M25-ROW()/100000,IF(O25="עודף",M25+ROW()/100000,""))
A26: אמר"לים ותצפית | B26: אמר"ל אקילה 6* | F26: 8 | K26: =IF($B26="","",SUM(C26:J26)) | L26: 8 | M26: =IF(OR($B26="",L26=""),"",K26-L26) | N26: =IF(OR($B26="",L26="",L26=0),"",K26/L26) | O26: =IF($B26="","",IF(L26="","אין מצאי",IF(K26<L26,"חוסר",IF(K26>L26,"עודף","תקין")))) | Q26: =IF(O26="חוסר",M26-ROW()/100000,IF(O26="עודף",M26+ROW()/100000,""))
A27: אמר"לים ותצפית | B27: אמר"ל דו עיני מיקרון | J27: 8 | K27: =IF($B27="","",SUM(C27:J27)) | M27: =IF(OR($B27="",L27=""),"",K27-L27) | N27: =IF(OR($B27="",L27="",L27=0),"",K27/L27) | O27: =IF($B27="","",IF(L27="","אין מצאי",IF(K27<L27,"חוסר",IF(K27>L27,"עודף","תקין")))) | Q27: =IF(O27="חוסר",M27-ROW()/100000,IF(O27="עודף",M27+ROW()/100000,""))
A28: אמר"לים ותצפית | B28: אמר"ל דו עיני עדי | C28: 2 | D28: 3 | E28: 3 | F28: 3 | G28: 12 | J28: 7 | K28: =IF($B28="","",SUM(C28:J28)) | L28: 30 | M28: =IF(OR($B28="",L28=""),"",K28-L28) | N28: =IF(OR($B28="",L28="",L28=0),"",K28/L28) | O28: =IF($B28="","",IF(L28="","אין מצאי",IF(K28<L28,"חוסר",IF(K28>L28,"עודף","תקין")))) | Q28: =IF(O28="חוסר",M28-ROW()/100000,IF(O28="עודף",M28+ROW()/100000,""))
A29: אמר"לים ותצפית | B29: אמר"ל דו עיני עידו | C29: 2 | D29: 2 | E29: 2 | F29: 2 | G29: 6 | H29: 2 | J29: 0 | K29: =IF($B29="","",SUM(C29:J29)) | L29: 17 | M29: =IF(OR($B29="",L29=""),"",K29-L29) | N29: =IF(OR($B29="",L29="",L29=0),"",K29/L29) | O29: =IF($B29="","",IF(L29="","אין מצאי",IF(K29<L29,"חוסר",IF(K29>L29,"עודף","תקין")))) | Q29: =IF(O29="חוסר",M29-ROW()/100000,IF(O29="עודף",M29+ROW()/100000,""))
A30: אמר"לים ותצפית | B30: אמר"ל שח"מ | C30: 13 | D30: 18 | E30: 16 | F30: 12 | G30: 0 | H30: 1 | J30: 13 | K30: =IF($B30="","",SUM(C30:J30)) | L30: 55 | M30: =IF(OR($B30="",L30=""),"",K30-L30) | N30: =IF(OR($B30="",L30="",L30=0),"",K30/L30) | O30: =IF($B30="","",IF(L30="","אין מצאי",IF(K30<L30,"חוסר",IF(K30>L30,"עודף","תקין")))) | Q30: =IF(O30="חוסר",M30-ROW()/100000,IF(O30="עודף",M30+ROW()/100000,""))
A31: אמר"לים ותצפית | B31: אמר"ל שח"ע | C31: 7 | D31: 10 | E31: 7 | F31: 8 | G31: 3 | H31: 4 | J31: 8 | K31: =IF($B31="","",SUM(C31:J31)) | L31: 47 | M31: =IF(OR($B31="",L31=""),"",K31-L31) | N31: =IF(OR($B31="",L31="",L31=0),"",K31/L31) | O31: =IF($B31="","",IF(L31="","אין מצאי",IF(K31<L31,"חוסר",IF(K31>L31,"עודף","תקין")))) | Q31: =IF(O31="חוסר",M31-ROW()/100000,IF(O31="עודף",M31+ROW()/100000,""))
A32: אמר"לים ותצפית | B32: חצובה למאתר | F32: 7 | K32: =IF($B32="","",SUM(C32:J32)) | M32: =IF(OR($B32="",L32=""),"",K32-L32) | N32: =IF(OR($B32="",L32="",L32=0),"",K32/L32) | O32: =IF($B32="","",IF(L32="","אין מצאי",IF(K32<L32,"חוסר",IF(K32>L32,"עודף","תקין")))) | Q32: =IF(O32="חוסר",M32-ROW()/100000,IF(O32="עודף",M32+ROW()/100000,""))
A33: אמר"לים ותצפית | B33: חצובה לעמית | C33: 1 | J33: 6 | K33: =IF($B33="","",SUM(C33:J33)) | M33: =IF(OR($B33="",L33=""),"",K33-L33) | N33: =IF(OR($B33="",L33="",L33=0),"",K33/L33) | O33: =IF($B33="","",IF(L33="","אין מצאי",IF(K33<L33,"חוסר",IF(K33>L33,"עודף","תקין")))) | Q33: =IF(O33="חוסר",M33-ROW()/100000,IF(O33="עודף",M33+ROW()/100000,""))
A34: אמר"לים ותצפית | B34: ישל"ט אורלי גיל | F34: 2 | K34: =IF($B34="","",SUM(C34:J34)) | L34: 2 | M34: =IF(OR($B34="",L34=""),"",K34-L34) | N34: =IF(OR($B34="",L34="",L34=0),"",K34/L34) | O34: =IF($B34="","",IF(L34="","אין מצאי",IF(K34<L34,"חוסר",IF(K34>L34,"עודף","תקין")))) | Q34: =IF(O34="חוסר",M34-ROW()/100000,IF(O34="עודף",M34+ROW()/100000,""))
A35: אמר"לים ותצפית | B35: ליאור | C35: 10 | D35: 11 | E35: 8 | F35: 8 | G35: 4 | J35: 4 | K35: =IF($B35="","",SUM(C35:J35)) | L35: 57 | M35: =IF(OR($B35="",L35=""),"",K35-L35) | N35: =IF(OR($B35="",L35="",L35=0),"",K35/L35) | O35: =IF($B35="","",IF(L35="","אין מצאי",IF(K35<L35,"חוסר",IF(K35>L35,"עודף","תקין")))) | Q35: =IF(O35="חוסר",M35-ROW()/100000,IF(O35="עודף",M35+ROW()/100000,""))
A36: אמר"לים ותצפית | B36: מאתר | F36: 10 | K36: =IF($B36="","",SUM(C36:J36)) | M36: =IF(OR($B36="",L36=""),"",K36-L36) | N36: =IF(OR($B36="",L36="",L36=0),"",K36/L36) | O36: =IF($B36="","",IF(L36="","אין מצאי",IF(K36<L36,"חוסר",IF(K36>L36,"עודף","תקין")))) | Q36: =IF(O36="חוסר",M36-ROW()/100000,IF(O36="עודף",M36+ROW()/100000,""))
A37: אמר"לים ותצפית | B37: מיני תבל נשלט | F37: 1 | K37: =IF($B37="","",SUM(C37:J37)) | L37: 1 | M37: =IF(OR($B37="",L37=""),"",K37-L37) | N37: =IF(OR($B37="",L37="",L37=0),"",K37/L37) | O37: =IF($B37="","",IF(L37="","אין מצאי",IF(K37<L37,"חוסר",IF(K37>L37,"עודף","תקין")))) | Q37: =IF(O37="חוסר",M37-ROW()/100000,IF(O37="עודף",M37+ROW()/100000,""))
A38: אמר"לים ותצפית | B38: מכבים | C38: 2 | D38: 3 | E38: 3 | F38: 3 | G38: 1 | J38: 1 | K38: =IF($B38="","",SUM(C38:J38)) | L38: 13 | M38: =IF(OR($B38="",L38=""),"",K38-L38) | N38: =IF(OR($B38="",L38="",L38=0),"",K38/L38) | O38: =IF($B38="","",IF(L38="","אין מצאי",IF(K38<L38,"חוסר",IF(K38>L38,"עודף","תקין")))) | Q38: =IF(O38="חוסר",M38-ROW()/100000,IF(O38="עודף",M38+ROW()/100000,""))
A39: אמר"לים ותצפית | B39: מכבית | C39: 2 | D39: 2 | E39: 2 | F39: 2 | J39: 4 | K39: =IF($B39="","",SUM(C39:J39)) | L39: 14 | M39: =IF(OR($B39="",L39=""),"",K39-L39) | N39: =IF(OR($B39="",L39="",L39=0),"",K39/L39) | O39: =IF($B39="","",IF(L39="","אין מצאי",IF(K39<L39,"חוסר",IF(K39>L39,"עודף","תקין")))) | Q39: =IF(O39="חוסר",M39-ROW()/100000,IF(O39="עודף",M39+ROW()/100000,""))
A40: אמר"לים ותצפית | B40: מצפן | C40: 6 | D40: 9 | E40: 6 | F40: 13 | H40: 5 | J40: 60 | K40: =IF($B40="","",SUM(C40:J40)) | M40: =IF(OR($B40="",L40=""),"",K40-L40) | N40: =IF(OR($B40="",L40="",L40=0),"",K40/L40) | O40: =IF($B40="","",IF(L40="","אין מצאי",IF(K40<L40,"חוסר",IF(K40>L40,"עודף","תקין")))) | Q40: =IF(O40="חוסר",M40-ROW()/100000,IF(O40="עודף",M40+ROW()/100000,""))
...

Sheet סיכום קטגוריה
A1: סיכום לפי קטגוריה (חי)
A2: קטגוריה | B2: פריטים | C2: סך יחידות | D2: סך מצאי | E2: סך פער | F2: חוסרים | G2: עודפים | H2: תקין
A3: נשק ומקלעים | B3: =COUNTIF('טבלת ניהול'!$A$3:$A$400,"נשק ומקלעים") | C3: =SUMIF('טבלת ניהול'!$A$3:$A$400,"נשק ומקלעים",'טבלת ניהול'!$K$3:$K$400) | D3: =SUMIF('טבלת ניהול'!$A$3:$A$400,"נשק ומקלעים",'טבלת ניהול'!$L$3:$L$400) | E3: =SUMIFS('טבלת ניהול'!$M$3:$M$400,'טבלת ניהול'!$A$3:$A$400,"נשק ומקלעים") | F3: =COUNTIFS('טבלת ניהול'!$A$3:$A$400,"נשק ומקלעים",'טבלת ניהול'!$O$3:$O$400,"חוסר") | G3: =COUNTIFS('טבלת ניהול'!$A$3:$A$400,"נשק ומקלעים",'טבלת ניהול'!$O$3:$O$400,"עודף") | H3: =COUNTIFS('טבלת ניהול'!$A$3:$A$400,"נשק ומקלעים",'טבלת ניהול'!$O$3:$O$400,"תקין")
A4: כוונות ואופטיקה | B4: =COUNTIF('טבלת ניהול'!$A$3:$A$400,"כוונות ואופטיקה") | C4: =SUMIF('טבלת ניהול'!$A$3:$A$400,"כוונות ואופטיקה",'טבלת ניהול'!$K$3:$K$400) | D4: =SUMIF('טבלת ניהול'!$A$3:$A$400,"כוונות ואופטיקה",'טבלת ניהול'!$L$3:$L$400) | E4: =SUMIFS('טבלת ניהול'!$M$3:$M$400,'טבלת ניהול'!$A$3:$A$400,"כוונות ואופטיקה") | F4: =COUNTIFS('טבלת ניהול'!$A$3:$A$400,"כוונות ואופטיקה",'טבלת ניהול'!$O$3:$O$400,"חוסר") | G4: =COUNTIFS('טבלת ניהול'!$A$3:$A$400,"כוונות ואופטיקה",'טבלת ניהול'!$O$3:$O$400,"עודף") | H4: =COUNTIFS('טבלת ניהול'!$A$3:$A$400,"כוונות ואופטיקה",'טבלת ניהול'!$O$3:$O$400,"תקין")
A5: אמר"לים ותצפית | B5: =COUNTIF('טבלת ניהול'!$A$3:$A$400,"אמר"לים ותצפית") | C5: =SUMIF('טבלת ניהול'!$A$3:$A$400,"אמר"לים ותצפית",'טבלת ניהול'!$K$3:$K$400) | D5: =SUMIF('טבלת ניהול'!$A$3:$A$400,"אמר"לים ותצפית",'טבלת ניהול'!$L$3:$L$400) | E5: =SUMIFS('טבלת ניהול'!$M$3:$M$400,'טבלת ניהול'!$A$3:$A$400,"אמר"לים ותצפית") | F5: =COUNTIFS('טבלת ניהול'!$A$3:$A$400,"אמר"לים ותצפית",'טבלת ניהול'!$O$3:$O$400,"חוסר") | G5: =COUNTIFS('טבלת ניהול'!$A$3:$A$400,"אמר"לים ותצפית",'טבלת ניהול'!$O$3:$O$400,"עודף") | H5: =COUNTIFS('טבלת ניהול'!$A$3:$A$400,"אמר"לים ותצפית",'טבלת ניהול'!$O$3:$O$400,"תקין")
A6: סמנים ומציינים | B6: =COUNTIF('טבלת ניהול'!$A$3:$A$400,"סמנים ומציינים") | C6: =SUMIF('טבלת ניהול'!$A$3:$A$400,"סמנים ומציינים",'טבלת ניהול'!$K$3:$K$400) | D6: =SUMIF('טבלת ניהול'!$A$3:$A$400,"סמנים ומציינים",'טבלת ניהול'!$L$3:$L$400) | E6: =SUMIFS('טבלת ניהול'!$M$3:$M$400,'טבלת ניהול'!$A$3:$A$400,"סמנים ומציינים") | F6: =COUNTIFS('טבלת ניהול'!$A$3:$A$400,"סמנים ומציינים",'טבלת ניהול'!$O$3:$O$400,"חוסר") | G6: =COUNTIFS('טבלת ניהול'!$A$3:$A$400,"סמנים ומציינים",'טבלת ניהול'!$O$3:$O$400,"עודף") | H6: =COUNTIFS('טבלת ניהול'!$A$3:$A$400,"סמנים ומציינים",'טבלת ניהול'!$O$3:$O$400,"תקין")
A7: מט"ל ואבזור | B7: =COUNTIF('טבלת ניהול'!$A$3:$A$400,"מט"ל ואבזור") | C7: =SUMIF('טבלת ניהול'!$A$3:$A$400,"מט"ל ואבזור",'טבלת ניהול'!$K$3:$K$400) | D7: =SUMIF('טבלת ניהול'!$A$3:$A$400,"מט"ל ואבזור",'טבלת ניהול'!$L$3:$L$400) | E7: =SUMIFS('טבלת ניהול'!$M$3:$M$400,'טבלת ניהול'!$A$3:$A$400,"מט"ל ואבזור") | F7: =COUNTIFS('טבלת ניהול'!$A$3:$A$400,"מט"ל ואבזור",'טבלת ניהול'!$O$3:$O$400,"חוסר") | G7: =COUNTIFS('טבלת ניהול'!$A$3:$A$400,"מט"ל ואבזור",'טבלת ניהול'!$O$3:$O$400,"עודף") | H7: =COUNTIFS('טבלת ניהול'!$A$3:$A$400,"מט"ל ואבזור",'טבלת ניהול'!$O$3:$O$400,"תקין")
A8: רחפנים | B8: =COUNTIF('טבלת ניהול'!$A$3:$A$400,"רחפנים") | C8: =SUMIF('טבלת ניהול'!$A$3:$A$400,"רחפנים",'טבלת ניהול'!$K$3:$K$400) | D8: =SUMIF('טבלת ניהול'!$A$3:$A$400,"רחפנים",'טבלת ניהול'!$L$3:$L$400) | E8: =SUMIFS('טבלת ניהול'!$M$3:$M$400,'טבלת ניהול'!$A$3:$A$400,"רחפנים") | F8: =COUNTIFS('טבלת ניהול'!$A$3:$A$400,"רחפנים",'טבלת ניהול'!$O$3:$O$400,"חוסר") | G8: =COUNTIFS('טבלת ניהול'!$A$3:$A$400,"רחפנים",'טבלת ניהול'!$O$3:$O$400,"עודף") | H8: =COUNTIFS('טבלת ניהול'!$A$3:$A$400,"רחפנים",'טבלת ניהול'!$O$3:$O$400,"תקין")
A9: חשמל ואנרגיה | B9: =COUNTIF('טבלת ניהול'!$A$3:$A$400,"חשמל ואנרגיה") | C9: =SUMIF('טבלת ניהול'!$A$3:$A$400,"חשמל ואנרגיה",'טבלת ניהול'!$K$3:$K$400) | D9: =SUMIF('טבלת ניהול'!$A$3:$A$400,"חשמל ואנרגיה",'טבלת ניהול'!$L$3:$L$400) | E9: =SUMIFS('טבלת ניהול'!$M$3:$M$400,'טבלת ניהול'!$A$3:$A$400,"חשמל ואנרגיה") | F9: =COUNTIFS('טבלת ניהול'!$A$3:$A$400,"חשמל ואנרגיה",'טבלת ניהול'!$O$3:$O$400,"חוסר") | G9: =COUNTIFS('טבלת ניהול'!$A$3:$A$400,"חשמל ואנרגיה",'טבלת ניהול'!$O$3:$O$400,"עודף") | H9: =COUNTIFS('טבלת ניהול'!$A$3:$A$400,"חשמל ואנרגיה",'טבלת ניהול'!$O$3:$O$400,"תקין")
A10: אחר | B10: =COUNTIF('טבלת ניהול'!$A$3:$A$400,"אחר") | C10: =SUMIF('טבלת ניהול'!$A$3:$A$400,"אחר",'טבלת ניהול'!$K$3:$K$400) | D10: =SUMIF('טבלת ניהול'!$A$3:$A$400,"אחר",'טבלת ניהול'!$L$3:$L$400) | E10: =SUMIFS('טבלת ניהול'!$M$3:$M$400,'טבלת ניהול'!$A$3:$A$400,"אחר") | F10: =COUNTIFS('טבלת ניהול'!$A$3:$A$400,"אחר",'טבלת ניהול'!$O$3:$O$400,"חוסר") | G10: =COUNTIFS('טבלת ניהול'!$A$3:$A$400,"אחר",'טבלת ניהול'!$O$3:$O$400,"עודף") | H10: =COUNTIFS('טבלת ניהול'!$A$3:$A$400,"אחר",'טבלת ניהול'!$O$3:$O$400,"תקין")
A11: סה"כ | B11: =SUM(B3:B10) | C11: =SUM(C3:C10) | D11: =SUM(D3:D10) | E11: =SUM(E3:E10) | F11: =SUM(F3:F10) | G11: =SUM(G3:G10) | H11: =SUM(H3:H10)

Sheet פילוח פלוגה
A1: פילוח אחזקה לפי פלוגה / גורם (חי)
A2: קטגוריה | B2: פלוגה א | C2: פלוגה ב | D2: פלוגה ג | E2: מסייעת | F2: פתן | G2: חפק | H2: מפקדה | I2: מלאי | J2: סך הכל
A3: נשק ומקלעים | B3: =SUMIF('טבלת ניהול'!$A$3:$A$400,"נשק ומקלעים",'טבלת ניהול'!$C$3:$C$400) | C3: =SUMIF('טבלת ניהול'!$A$3:$A$400,"נשק ומקלעים",'טבלת ניהול'!$D$3:$D$400) | D3: =SUMIF('טבלת ניהול'!$A$3:$A$400,"נשק ומקלעים",'טבלת ניהול'!$E$3:$E$400) | E3: =SUMIF('טבלת ניהול'!$A$3:$A$400,"נשק ומקלעים",'טבלת ניהול'!$F$3:$F$400) | F3: =SUMIF('טבלת ניהול'!$A$3:$A$400,"נשק ומקלעים",'טבלת ניהול'!$G$3:$G$400) | G3: =SUMIF('טבלת ניהול'!$A$3:$A$400,"נשק ומקלעים",'טבלת ניהול'!$H$3:$H$400) | H3: =SUMIF('טבלת ניהול'!$A$3:$A$400,"נשק ומקלעים",'טבלת ניהול'!$I$3:$I$400) | I3: =SUMIF('טבלת ניהול'!$A$3:$A$400,"נשק ומקלעים",'טבלת ניהול'!$J$3:$J$400) | J3: =SUMIF('טבלת ניהול'!$A$3:$A$400,"נשק ומקלעים",'טבלת ניהול'!$K$3:$K$400)
A4: כוונות ואופטיקה | B4: =SUMIF('טבלת ניהול'!$A$3:$A$400,"כוונות ואופטיקה",'טבלת ניהול'!$C$3:$C$400) | C4: =SUMIF('טבלת ניהול'!$A$3:$A$400,"כוונות ואופטיקה",'טבלת ניהול'!$D$3:$D$400) | D4: =SUMIF('טבלת ניהול'!$A$3:$A$400,"כוונות ואופטיקה",'טבלת ניהול'!$E$3:$E$400) | E4: =SUMIF('טבלת ניהול'!$A$3:$A$400,"כוונות ואופטיקה",'טבלת ניהול'!$F$3:$F$400) | F4: =SUMIF('טבלת ניהול'!$A$3:$A$400,"כוונות ואופטיקה",'טבלת ניהול'!$G$3:$G$400) | G4: =SUMIF('טבלת ניהול'!$A$3:$A$400,"כוונות ואופטיקה",'טבלת ניהול'!$H$3:$H$400) | H4: =SUMIF('טבלת ניהול'!$A$3:$A$400,"כוונות ואופטיקה",'טבלת ניהול'!$I$3:$I$400) | I4: =SUMIF('טבלת ניהול'!$A$3:$A$400,"כוונות ואופטיקה",'טבלת ניהול'!$J$3:$J$400) | J4: =SUMIF('טבלת ניהול'!$A$3:$A$400,"כוונות ואופטיקה",'טבלת ניהול'!$K$3:$K$400)
A5: אמר"לים ותצפית | B5: =SUMIF('טבלת ניהול'!$A$3:$A$400,"אמר"לים ותצפית",'טבלת ניהול'!$C$3:$C$400) | C5: =SUMIF('טבלת ניהול'!$A$3:$A$400,"אמר"לים ותצפית",'טבלת ניהול'!$D$3:$D$400) | D5: =SUMIF('טבלת ניהול'!$A$3:$A$400,"אמר"לים ותצפית",'טבלת ניהול'!$E$3:$E$400) | E5: =SUMIF('טבלת ניהול'!$A$3:$A$400,"אמר"לים ותצפית",'טבלת ניהול'!$F$3:$F$400) | F5: =SUMIF('טבלת ניהול'!$A$3:$A$400,"אמר"לים ותצפית",'טבלת ניהול'!$G$3:$G$400) | G5: =SUMIF('טבלת ניהול'!$A$3:$A$400,"אמר"לים ותצפית",'טבלת ניהול'!$H$3:$H$400) | H5: =SUMIF('טבלת ניהול'!$A$3:$A$400,"אמר"לים ותצפית",'טבלת ניהול'!$I$3:$I$400) | I5: =SUMIF('טבלת ניהול'!$A$3:$A$400,"אמר"לים ותצפית",'טבלת ניהול'!$J$3:$J$400) | J5: =SUMIF('טבלת ניהול'!$A$3:$A$400,"אמר"לים ותצפית",'טבלת ניהול'!$K$3:$K$400)
A6: סמנים ומציינים | B6: =SUMIF('טבלת ניהול'!$A$3:$A$400,"סמנים ומציינים",'טבלת ניהול'!$C$3:$C$400) | C6: =SUMIF('טבלת ניהול'!$A$3:$A$400,"סמנים ומציינים",'טבלת ניהול'!$D$3:$D$400) | D6: =SUMIF('טבלת ניהול'!$A$3:$A$400,"סמנים ומציינים",'טבלת ניהול'!$E$3:$E$400) | E6: =SUMIF('טבלת ניהול'!$A$3:$A$400,"סמנים ומציינים",'טבלת ניהול'!$F$3:$F$400) | F6: =SUMIF('טבלת ניהול'!$A$3:$A$400,"סמנים ומציינים",'טבלת ניהול'!$G$3:$G$400) | G6: =SUMIF('טבלת ניהול'!$A$3:$A$400,"סמנים ומציינים",'טבלת ניהול'!$H$3:$H$400) | H6: =SUMIF('טבלת ניהול'!$A$3:$A$400,"סמנים ומציינים",'טבלת ניהול'!$I$3:$I$400) | I6: =SUMIF('טבלת ניהול'!$A$3:$A$400,"סמנים ומציינים",'טבלת ניהול'!$J$3:$J$400) | J6: =SUMIF('טבלת ניהול'!$A$3:$A$400,"סמנים ומציינים",'טבלת ניהול'!$K$3:$K$400)
A7: מט"ל ואבזור | B7: =SUMIF('טבלת ניהול'!$A$3:$A$400,"מט"ל ואבזור",'טבלת ניהול'!$C$3:$C$400) | C7: =SUMIF('טבלת ניהול'!$A$3:$A$400,"מט"ל ואבזור",'טבלת ניהול'!$D$3:$D$400) | D7: =SUMIF('טבלת ניהול'!$A$3:$A$400,"מט"ל ואבזור",'טבלת ניהול'!$E$3:$E$400) | E7: =SUMIF('טבלת ניהול'!$A$3:$A$400,"מט"ל ואבזור",'טבלת ניהול'!$F$3:$F$400) | F7: =SUMIF('טבלת ניהול'!$A$3:$A$400,"מט"ל ואבזור",'טבלת ניהול'!$G$3:$G$400) | G7: =SUMIF('טבלת ניהול'!$A$3:$A$400,"מט"ל ואבזור",'טבלת ניהול'!$H$3:$H$400) | H7: =SUMIF('טבלת ניהול'!$A$3:$A$400,"מט"ל ואבזור",'טבלת ניהול'!$I$3:$I$400) | I7: =SUMIF('טבלת ניהול'!$A$3:$A$400,"מט"ל ואבזור",'טבלת ניהול'!$J$3:$J$400) | J7: =SUMIF('טבלת ניהול'!$A$3:$A$400,"מט"ל ואבזור",'טבלת ניהול'!$K$3:$K$400)
A8: רחפנים | B8: =SUMIF('טבלת ניהול'!$A$3:$A$400,"רחפנים",'טבלת ניהול'!$C$3:$C$400) | C8: =SUMIF('טבלת ניהול'!$A$3:$A$400,"רחפנים",'טבלת ניהול'!$D$3:$D$400) | D8: =SUMIF('טבלת ניהול'!$A$3:$A$400,"רחפנים",'טבלת ניהול'!$E$3:$E$400) | E8: =SUMIF('טבלת ניהול'!$A$3:$A$400,"רחפנים",'טבלת ניהול'!$F$3:$F$400) | F8: =SUMIF('טבלת ניהול'!$A$3:$A$400,"רחפנים",'טבלת ניהול'!$G$3:$G$400) | G8: =SUMIF('טבלת ניהול'!$A$3:$A$400,"רחפנים",'טבלת ניהול'!$H$3:$H$400) | H8: =SUMIF('טבלת ניהול'!$A$3:$A$400,"רחפנים",'טבלת ניהול'!$I$3:$I$400) | I8: =SUMIF('טבלת ניהול'!$A$3:$A$400,"רחפנים",'טבלת ניהול'!$J$3:$J$400) | J8: =SUMIF('טבלת ניהול'!$A$3:$A$400,"רחפנים",'טבלת ניהול'!$K$3:$K$400)
A9: חשמל ואנרגיה | B9: =SUMIF('טבלת ניהול'!$A$3:$A$400,"חשמל ואנרגיה",'טבלת ניהול'!$C$3:$C$400) | C9: =SUMIF('טבלת ניהול'!$A$3:$A$400,"חשמל ואנרגיה",'טבלת ניהול'!$D$3:$D$400) | D9: =SUMIF('טבלת ניהול'!$A$3:$A$400,"חשמל ואנרגיה",'טבלת ניהול'!$E$3:$E$400) | E9: =SUMIF('טבלת ניהול'!$A$3:$A$400,"חשמל ואנרגיה",'טבלת ניהול'!$F$3:$F$400) | F9: =SUMIF('טבלת ניהול'!$A$3:$A$400,"חשמל ואנרגיה",'טבלת ניהול'!$G$3:$G$400) | G9: =SUMIF('טבלת ניהול'!$A$3:$A$400,"חשמל ואנרגיה",'טבלת ניהול'!$H$3:$H$400) | H9: =SUMIF('טבלת ניהול'!$A$3:$A$400,"חשמל ואנרגיה",'טבלת ניהול'!$I$3:$I$400) | I9: =SUMIF('טבלת ניהול'!$A$3:$A$400,"חשמל ואנרגיה",'טבלת ניהול'!$J$3:$J$400) | J9: =SUMIF('טבלת ניהול'!$A$3:$A$400,"חשמל ואנרגיה",'טבלת ניהול'!$K$3:$K$400)
A10: אחר | B10: =SUMIF('טבלת ניהול'!$A$3:$A$400,"אחר",'טבלת ניהול'!$C$3:$C$400) | C10: =SUMIF('טבלת ניהול'!$A$3:$A$400,"אחר",'טבלת ניהול'!$D$3:$D$400) | D10: =SUMIF('טבלת ניהול'!$A$3:$A$400,"אחר",'טבלת ניהול'!$E$3:$E$400) | E10: =SUMIF('טבלת ניהול'!$A$3:$A$400,"אחר",'טבלת ניהול'!$F$3:$F$400) | F10: =SUMIF('טבלת ניהול'!$A$3:$A$400,"אחר",'טבלת ניהול'!$G$3:$G$400) | G10: =SUMIF('טבלת ניהול'!$A$3:$A$400,"אחר",'טבלת ניהול'!$H$3:$H$400) | H10: =SUMIF('טבלת ניהול'!$A$3:$A$400,"אחר",'טבלת ניהול'!$I$3:$I$400) | I10: =SUMIF('טבלת ניהול'!$A$3:$A$400,"אחר",'טבלת ניהול'!$J$3:$J$400) | J10: =SUMIF('טבלת ניהול'!$A$3:$A$400,"אחר",'טבלת ניהול'!$K$3:$K$400)
A11: סה"כ | B11: =SUM(B3:B10) | C11: =SUM(C3:C10) | D11: =SUM(D3:D10) | E11: =SUM(E3:E10) | F11: =SUM(F3:F10) | G11: =SUM(G3:G10) | H11: =SUM(H3:H10) | I11: =SUM(I3:I10) | J11: =SUM(J3:J10)

Sheet מקרא והוראות
A1: איך מעלים ומשתמשים ב-Google Sheets
A3: העלאה נכונה | B3: אל תעתיק תאים. ב-Drive: New ◂ File upload ◂ קליק ימני על הקובץ ◂ Open with ◂ Google Sheets
A4: חלופה | B4: בתוך גיליון: File ◂ Import ◂ Upload ◂ Insert new sheet(s) — שומר את הנוסחאות
A5: עריכה | B5: ערוך רק בלשונית "טבלת ניהול": כמות אצל פלוגה, מלאי, מצאי — כל השאר מתעדכן לבד
A6: הוספת פריט | B6: כתוב בשורה ריקה מתחת לרשימה — הנוסחאות כבר פרוסות עד שורה 400 ויחושבו מיד
A7: קטגוריה | B7: בחר מרשימה נפתחת (Data validation עובר ב-import)
A8: חוסר (אדום) | B8: סך הכל קטן מהמצאי הרשום
A9: עודף (כתום) | B9: סך הכל גדול מהמצאי הרשום
A10: תקין (ירוק) | B10: התאמה מלאה
A11: אין מצאי (אפור) | B11: לא הוזן מצאי
A12: הערה | B12: הקובץ נבנה בלי "טבלת Excel" כי Google Sheets לא תומך בהפניות מבניות (Otzma[...])

Sheet רשימות
A1: קטגוריות
A2: נשק ומקלעים
A3: כוונות ואופטיקה
A4: אמר"לים ותצפית
A5: סמנים ומציינים
A6: מט"ל ואבזור
A7: רחפנים
A8: חשמל ואנרגיה
A9: אחר
